Workbook

Sheet Clientes
A1: Código | B1: Nombre | C1: NIF | D1: Dirección | E1: CP | F1: Ciudad | G1: Provincia | H1: Teléfono | I1: Email | J1: Fecha alta | K1: Activo | L1: Límite crédito | M1: Saldo pendiente | N1: Riesgo | O1: Notas internas
A2: C0001 | B2: Talleres Díaz | C2: J81494521 | D2: C/ Doctor Fleming, 124 | E2: 48490 | F2: Bilbao | G2: Bizkaia | H2: 977 290 767 | I2: diaz1@talleres.es | J2: 45712 | K2: TRUE | L2: 10000 | M2: 11594.38 | N2: =IF(M2>L2,"Alto",IF(M2>L2*0.8,"Medio","Bajo")) -> Alto | O2: Revisar condiciones de pago
A3: C0002 | B3: Núñez & Asociados | C3: B51508096 | D3: C/ del Sol, 82 | E3: 08308 | F3: Barcelona | G3: Barcelona | H3: 976 608 153 | I3: nunez2@nunez.es | J3: 45048 | K3: TRUE | L3: 20000 | M3: 19565.74 | N3: =IF(M3>L3,"Alto",IF(M3>L3*0.8,"Medio","Bajo")) -> Medio
A4: C0003 | B4: Distribuciones Alonso S.A. | C4: B38637057 | D4: Paseo de la Castellana, 2 | E4: 28326 | F4: Alcalá de Henares | G4: Madrid | H4: 918 867 474 | I4: alonso3@distribuciones.es | J4: 42509 | K4: TRUE | L4: 5000 | M4: 3076.76 | N4: =IF(M4>L4,"Alto",IF(M4>L4*0.8,"Medio","Bajo")) -> Bajo
A5: C0004 | B5: Clínica Dental Gil | C5: B62216382 | D5: Avda. de la Constitución, 31 | E5: 15568 | F5: A Coruña | G5: A Coruña | H5: 933 803 212 | I5: gil4@clinica.es | J5: 45606 | K5: FALSE | L5: 3000 | M5: 227.96 | N5: =IF(M5>L5,"Alto",IF(M5>L5*0.8,"Medio","Bajo")) -> Bajo
A6: C0005 | B6: Ferretería Vázquez S.L. | C6: B56730317 | D6: Paseo de la Castellana, 138 | E6: 28419 | F6: Alcalá de Henares | G6: Madrid | H6: 935 987 297 | I6: vazquez5@ferreteria.es | J6: 44777 | K6: TRUE | L6: 20000 | M6: 14343.86 | N6: =IF(M6>L6,"Alto",IF(M6>L6*0.8,"Medio","Bajo")) -> Bajo
A7: C0006 | B7: Agüero & Asociados | C7: A74581691 | D7: C/ Doctor Fleming, 114 | E7: 12071 | F7: Castelló de la Plana | G7: Castellón | H7: 958 488 876 | I7: aguero6@aguero.es | J7: 45201 | K7: TRUE | L7: 5000 | M7: 88.96 | N7: =IF(M7>L7,"Alto",IF(M7>L7*0.8,"Medio","Bajo")) -> Bajo
A8: C0007 | B8: Vázquez e Hijos S.L. | C8: J74880488 | D8: C/ San Juan, 130 | E8: 12746 | F8: Castelló de la Plana | G8: Castellón | H8: 914 807 189 | I8: vazquez7@vazquez.es | J8: 45632 | K8: TRUE | L8: 10000 | M8: 5552.27 | N8: =IF(M8>L8,"Alto",IF(M8>L8*0.8,"Medio","Bajo")) -> Bajo
A9: C0008 | B9: Molina & Asociados | C9: J74680318 | D9: C/ Real, 82 | E9: 12897 | F9: Castelló de la Plana | G9: Castellón | H9: 959 121 877 | I9: molina8@molina.es | J9: 43631 | K9: TRUE | L9: 10000 | M9: 2011.83 | N9: =IF(M9>L9,"Alto",IF(M9>L9*0.8,"Medio","Bajo")) -> Bajo
A10: C0009 | B10: Transportes Torres S.L. | C10: J57457543 | D10: C/ Doctor Fleming, 9 | E10: 41778 | F10: Sevilla | G10: Sevilla | H10: 964 544 928 | I10: torres9@transportes.es | J10: 43376 | K10: TRUE | L10: 10000 | M10: 9005.86 | N10: =IF(M10>L10,"Alto",IF(M10>L10*0.8,"Medio","Bajo")) -> Medio
A11: C0010 | B11: Talleres García | C11: B88298837 | D11: Avda. de la Constitución, 17 | E11: 12094 | F11: Castelló de la Plana | G11: Castellón | H11: 920 686 220 | I11: garcia10@talleres.es | J11: 42818 | K11: TRUE | L11: 5000 | M11: 5700.6 | N11: =IF(M11>L11,"Alto",IF(M11>L11*0.8,"Medio","Bajo")) -> Alto | O11: Revisar condiciones de pago
A12: C0011 | B12: Transportes García S.L. | C12: J59851176 | D12: C/ Real, 117 | E12: 26540 | F12: Logroño | G12: La Rioja | H12: 910 979 259 | I12: garcia11@transportes.es | J12: 43698 | K12: FALSE | L12: 3000 | M12: 2929.78 | N12: =IF(M12>L12,"Alto",IF(M12>L12*0.8,"Medio","Bajo")) -> Medio
A13: C0012 | B13: Ferretería López S.L. | C13: J40604363 | D13: C/ Mayor, 5 | E13: 50810 | F13: Zaragoza | G13: Zaragoza | H13: 996 215 442 | I13: lopez12@ferreteria.es | J13: 43506 | K13: FALSE | L13: 20000 | M13: 20809.82 | N13: =IF(M13>L13,"Alto",IF(M13>L13*0.8,"Medio","Bajo")) -> Alto | O13: Revisar condiciones de pago
A14: C0013 | B14: Panadería García | C14: B53864598 | D14: Rambla de Catalunya, 70 | E14: 15633 | F14: A Coruña | G14: A Coruña | H14: 977 231 836 | I14: garcia13@panaderia.es | J14: 43366 | K14: FALSE | L14: 20000 | M14: 11897.27 | N14: =IF(M14>L14,"Alto",IF(M14>L14*0.8,"Medio","Bajo")) -> Bajo
A15: C0014 | B15: Distribuciones Muñoz S.A. | C15: A44677957 | D15: Rambla de Catalunya, 83 | E15: 50858 | F15: Zaragoza | G15: Zaragoza | H15: 922 277 524 | I15: munoz14@distribuciones.es | J15: 44174 | K15: FALSE | L15: 20000 | M15: 13074.18 | N15: =IF(M15>L15,"Alto",IF(M15>L15*0.8,"Medio","Bajo")) -> Bajo
A16: C0015 | B16: Ferretería Alonso S.L. | C16: A30020377 | D16: C/ Mayor, 127 | E16: 28024 | F16: Madrid | G16: Madrid | H16: 953 290 469 | I16: alonso15@ferreteria.es | J16: 45019 | K16: TRUE | L16: 10000 | M16: 7371.37 | N16: =IF(M16>L16,"Alto",IF(M16>L16*0.8,"Medio","Bajo")) -> Bajo
A17: C0016 | B17: Transportes Núñez S.L. | C17: B46126863 | D17: Avda. de la Constitución, 49 | E17: 14586 | F17: Córdoba | G17: Córdoba | H17: 938 880 143 | I17: nunez16@transportes.es | J17: 43176 | K17: FALSE | L17: 3000 | M17: 1244.77 | N17: =IF(M17>L17,"Alto",IF(M17>L17*0.8,"Medio","Bajo")) -> Bajo
A18: C0017 | B18: Construcciones Serrano S.L.U. | C18: B15552760 | D18: Avda. de la Constitución, 128 | E18: 29829 | F18: Málaga | G18: Málaga | H18: 940 788 913 | I18: serrano17@construcciones.es | J18: 42533 | K18: TRUE | L18: 20000 | M18: 14792.88 | N18: =IF(M18>L18,"Alto",IF(M18>L18*0.8,"Medio","Bajo")) -> Bajo
A19: C0018 | B19: Talleres Muñoz | C19: J48112960 | D19: C/ San Juan, 117 | E19: 26878 | F19: Logroño | G19: La Rioja | H19: 946 847 493 | I19: munoz18@talleres.es | J19: 45721 | K19: TRUE | L19: 20000 | M19: 5630.04 | N19: =IF(M19>L19,"Alto",IF(M19>L19*0.8,"Medio","Bajo")) -> Bajo
A20: C0019 | B20: Farmacia Núñez | C20: B31241074 | D20: Rambla de Catalunya, 45 | E20: 08377 | F20: L'Hospitalet de Llobregat | G20: Barcelona | H20: 945 323 944 | I20: nunez19@farmacia.es | J20: 42140 | K20: FALSE | L20: 5000 | M20: 2302.44 | N20: =IF(M20>L20,"Alto",IF(M20>L20*0.8,"Medio","Bajo")) -> Bajo
A21: C0020 | B21: Ibáñez e Hijos S.L. | C21: A80112876 | D21: C/ Doctor Fleming, 114 | E21: 29099 | F21: Málaga | G21: Málaga | H21: 963 250 682 | I21: ibanez20@ibanez.es | J21: 44055 | K21: FALSE | L21: 20000 | M21: 23825.03 | N21: =IF(M21>L21,"Alto",IF(M21>L21*0.8,"Medio","Bajo")) -> Alto | O21: Revisar condiciones de pago
A22: C0021 | B22: Ferretería Serrano S.L. | C22: B76247715 | D22: Rambla de Catalunya, 61 | E22: 08809 | F22: L'Hospitalet de Llobregat | G22: Barcelona | H22: 937 618 972 | I22: serrano21@ferreteria.es | J22: 43277 | K22: FALSE | L22: 20000 | M22: 6794.41 | N22: =IF(M22>L22,"Alto",IF(M22>L22*0.8,"Medio","Bajo")) -> Bajo
A23: C0022 | B23: Molina & Asociados | C23: A74896494 | D23: Plaza de España, 79 | E23: 28311 | F23: Madrid | G23: Madrid | H23: 948 946 114 | I23: molina22@molina.es | J23: 45809 | K23: TRUE | L23: 10000 | M23: 9652.2 | N23: =IF(M23>L23,"Alto",IF(M23>L23*0.8,"Medio","Bajo")) -> Medio
A24: C0023 | B24: Ferretería Núñez S.L. | C24: J68267378 | D24: Plaza de España, 72 | E24: 29258 | F24: Málaga | G24: Málaga | H24: 974 475 459 | I24: nunez23@ferreteria.es | J24: 44835 | K24: FALSE | L24: 3000 | M24: 1553.44 | N24: =IF(M24>L24,"Alto",IF(M24>L24*0.8,"Medio","Bajo")) -> Bajo
A25: C0024 | B25: Ramos & Asociados | C25: B25389167 | D25: C/ San Juan, 133 | E25: 11029 | F25: Cádiz | G25: Cádiz | H25: 933 907 627 | I25: ramos24@ramos.es | J25: 45692 | K25: TRUE | L25: 10000 | M25: 749.18 | N25: =IF(M25>L25,"Alto",IF(M25>L25*0.8,"Medio","Bajo")) -> Bajo
A26: C0025 | B26: Construcciones Vázquez S.L.U. | C26: J99237907 | D26: C/ Doctor Fleming, 121 | E26: 08443 | F26: L'Hospitalet de Llobregat | G26: Barcelona | H26: 955 920 360 | I26: vazquez25@construcciones.es | J26: 43442 | K26: TRUE | L26: 3000 | M26: 2144.71 | N26: =IF(M26>L26,"Alto",IF(M26>L26*0.8,"Medio","Bajo")) -> Bajo
A27: C0026 | B27: Gómez & Asociados | C27: A53658882 | D27: C/ Real, 46 | E27: 33310 | F27: Gijón | G27: Asturias | H27: 965 723 441 | I27: gomez26@gomez.es | J27: 44960 | K27: FALSE | L27: 5000 | M27: 4290.95 | N27: =IF(M27>L27,"Alto",IF(M27>L27*0.8,"Medio","Bajo")) -> Medio
A28: C0027 | B28: Construcciones Agüero S.L.U. | C28: B48503801 | D28: Paseo de la Castellana, 47 | E28: 11308 | F28: Cádiz | G28: Cádiz | H28: 951 782 702 | I28: aguero27@construcciones.es | J28: 42009 | K28: TRUE | L28: 3000 | M28: 1494.29 | N28: =IF(M28>L28,"Alto",IF(M28>L28*0.8,"Medio","Bajo")) -> Bajo
A29: C0028 | B29: Panadería Hernández | C29: A32267189 | D29: Rambla de Catalunya, 32 | E29: 46421 | F29: Valencia | G29: Valencia | H29: 990 988 395 | I29: hernandez28@panaderia.es | J29: 44431 | K29: FALSE | L29: 5000 | M29: 4064.2 | N29: =IF(M29>L29,"Alto",IF(M29>L29*0.8,"Medio","Bajo")) -> Medio
A30: C0029 | B30: Transportes García S.L. | C30: B83721279 | D30: C/ del Sol, 45 | E30: 50162 | F30: Zaragoza | G30: Zaragoza | H30: 945 727 421 | I30: garcia29@transportes.es | J30: 43956 | K30: TRUE | L30: 10000 | M30: 2061.6 | N30: =IF(M30>L30,"Alto",IF(M30>L30*0.8,"Medio","Bajo")) -> Bajo
A31: C0030 | B31: Distribuciones Gómez S.A. | C31: A33010187 | D31: Plaza de España, 5 | E31: 08760 | F31: Barcelona | G31: Barcelona | H31: 928 662 783 | I31: gomez30@distribuciones.es | J31: 43643 | K31: TRUE | L31: 3000 | M31: 2334.07 | N31: =IF(M31>L31,"Alto",IF(M31>L31*0.8,"Medio","Bajo")) -> Bajo
A32: C0031 | B32: Farmacia Ibáñez | C32: J59024298 | D32: C/ Real, 128 | E32: 28821 | F32: Madrid | G32: Madrid | H32: 912 948 560 | I32: ibanez31@farmacia.es | J32: 45605 | K32: FALSE | L32: 5000 | M32: 5461.04 | N32: =IF(M32>L32,"Alto",IF(M32>L32*0.8,"Medio","Bajo")) -> Alto | O32: Revisar condiciones de pago
A33: C0032 | B33: Construcciones Torres S.L.U. | C33: A79430409 | D33: Plaza de España, 35 | E33: 11756 | F33: Cádiz | G33: Cádiz | H33: 992 250 310 | I33: torres32@construcciones.es | J33: 44334 | K33: FALSE | L33: 3000 | M33: 1158.66 | N33: =IF(M33>L33,"Alto",IF(M33>L33*0.8,"Medio","Bajo")) -> Bajo
A34: C0033 | B34: Distribuciones López S.A. | C34: J63461428 | D34: C/ Doctor Fleming, 130 | E34: 50231 | F34: Zaragoza | G34: Zaragoza | H34: 968 605 178 | I34: lopez33@distribuciones.es | J34: 44821 | K34: TRUE | L34: 10000 | M34: 4529.87 | N34: =IF(M34>L34,"Alto",IF(M34>L34*0.8,"Medio","Bajo")) -> Bajo
A35: C0034 | B35: Distribuciones García S.A. | C35: B30514277 | D35: C/ San Juan, 36 | E35: 50836 | F35: Zaragoza | G35: Zaragoza | H35: 994 380 301 | I35: garcia34@distribuciones.es | J35: 45171 | K35: TRUE | L35: 3000 | M35: 2342.88 | N35: =IF(M35>L35,"Alto",IF(M35>L35*0.8,"Medio","Bajo")) -> Bajo
A36: C0035 | B36: Clínica Dental Sánchez | C36: B83577660 | D36: Avda. de la Constitución, 134 | E36: 08031 | F36: L'Hospitalet de Llobregat | G36: Barcelona | H36: 960 447 362 | I36: sanchez35@clinica.es | J36: 45482 | K36: TRUE | L36: 10000 | M36: 2671.63 | N36: =IF(M36>L36,"Alto",IF(M36>L36*0.8,"Medio","Bajo")) -> Bajo
A37: C0036 | B37: Farmacia Ramos | C37: A51352365 | D37: C/ San Juan, 114 | E37: 41103 | F37: Sevilla | G37: Sevilla | H37: 980 365 127 | I37: ramos36@farmacia.es | J37: 44956 | K37: TRUE | L37: 5000 | M37: 3409.37 | N37: =IF(M37>L37,"Alto",IF(M37>L37*0.8,"Medio","Bajo")) -> Bajo
A38: C0037 | B38: Blanco & Asociados | C38: A36430843 | D38: Paseo de la Castellana, 14 | E38: 12718 | F38: Castelló de la Plana | G38: Castellón | H38: 961 929 709 | I38: blanco37@blanco.es | J38: 45190 | K38: TRUE | L38: 20000 | M38: 9129.29 | N38: =IF(M38>L38,"Alto",IF(M38>L38*0.8,"Medio","Bajo")) -> Bajo
A39: C0038 | B39: Clínica Dental Moreno | C39: B53306595 | D39: C/ Real, 80 | E39: 05347 | F39: Ávila | G39: Ávila | H39: 989 409 222 | I39: moreno38@clinica.es | J39: 43274 | K39: TRUE | L39: 10000 | M39: 9234.67 | N39: =IF(M39>L39,"Alto",IF(M39>L39*0.8,"Medio","Bajo")) -> Medio
A40: C0039 | B40: Farmacia Sánchez | C40: J79417210 | D40: C/ del Sol, 58 | E40: 29229 | F40: Málaga | G40: Málaga | H40: 920 874 325 | I40: sanchez39@farmacia.es | J40: 44222 | K40: FALSE | L40: 10000 | M40: 7915.77 | N40: =IF(M40>L40,"Alto",IF(M40>L40*0.8,"Medio","Bajo")) -> Bajo
...

Sheet Inventario
A1: Producto | D1: Existencias | G1: Valoración | J1: Análisis
A2: SKU | B2: Descripción | C2: Categoría | D2: Stock | E2: Mínimo | F2: Ubicación | G2: Coste unitario | H2: PVP | I2: Valor stock | J2: Reponer | K2: Margen
A3: SKU-10000 | B3: Electricidad ref. 499 | C3: Electricidad | D3: 137 | E3: 25 | F3: Pasillo 6 - A1 | G3: 58.39 | H3: 110.38 | I3: =D3*G3 -> 7999.43 | J3: =IF(D3<E3,"Sí","No") -> No | K3: =IF(H3=0,0,(H3-G3)/H3) -> 0.47100924
A4: SKU-10007 | B4: Tornillería ref. 334 | C4: Tornillería | D4: 115 | E4: 50 | F4: Pasillo 6 - D2 | G4: 37.55 | H4: 77.37 | I4: =D4*G4 -> 4318.25 | J4: =IF(D4<E4,"Sí","No") -> No | K4: =IF(H4=0,0,(H4-G4)/H4) -> 0.51466977
A5: SKU-10014 | B5: Herramienta ref. 393 | C5: Herramientas | D5: 44 | E5: 10 | F5: Pasillo 4 - D2 | G5: 72.67 | H5: 106.69 | I5: =D5*G5 -> 3197.48 | J5: =IF(D5<E5,"Sí","No") -> No | K5: =IF(H5=0,0,(H5-G5)/H5) -> 0.31886775
A6: SKU-10021 | B6: Fontanería ref. 670 | C6: Fontanería | D6: 266 | E6: 10 | F6: Pasillo 6 - B2 | G6: 7.3 | H6: 10.96 | I6: =D6*G6 -> 1941.8 | J6: =IF(D6<E6,"Sí","No") -> No | K6: =IF(H6=0,0,(H6-G6)/H6) -> 0.33394161
A7: SKU-10028 | B7: Pintura ref. 667 | C7: Pintura | D7: 79 | E7: 20 | F7: Pasillo 8 - B2 | G7: 38.85 | H7: 78.5 | I7: =D7*G7 -> 3069.15 | J7: =IF(D7<E7,"Sí","No") -> No | K7: =IF(H7=0,0,(H7-G7)/H7) -> 0.50509554
A8: SKU-10035 | B8: Jardín ref. 615 | C8: Jardín | D8: 14 | E8: 25 | F8: Pasillo 4 - C4 | G8: 32.71 | H8: 57.88 | I8: =D8*G8 -> 457.94 | J8: =IF(D8<E8,"Sí","No") -> Sí | K8: =IF(H8=0,0,(H8-G8)/H8) -> 0.43486524
A9: SKU-10042 | B9: Fontanería ref. 896 | C9: Fontanería | D9: 247 | E9: 20 | F9: Pasillo 8 - A3 | G9: 17.55 | H9: 30.62 | I9: =D9*G9 -> 4334.85 | J9: =IF(D9<E9,"Sí","No") -> No | K9: =IF(H9=0,0,(H9-G9)/H9) -> 0.4268452
A10: SKU-10049 | B10: Herramienta ref. 917 | C10: Herramientas | D10: 84 | E10: 20 | F10: Pasillo 1 - B2 | G10: 32.86 | H10: 56.43 | I10: =D10*G10 -> 2760.24 | J10: =IF(D10<E10,"Sí","No") -> No | K10: =IF(H10=0,0,(H10-G10)/H10) -> 0.41768563
A11: SKU-10056 | B11: Pintura ref. 531 | C11: Pintura | D11: 94 | E11: 10 | F11: Pasillo 2 - D5 | G11: 3.23 | H11: 5.7 | I11: =D11*G11 -> 303.62 | J11: =IF(D11<E11,"Sí","No") -> No | K11: =IF(H11=0,0,(H11-G11)/H11) -> 0.43333333
A12: SKU-10063 | B12: Pintura ref. 857 | C12: Pintura | D12: 106 | E12: 20 | F12: Pasillo 8 - B5 | G12: 27.66 | H12: 47.27 | I12: =D12*G12 -> 2931.96 | J12: =IF(D12<E12,"Sí","No") -> No | K12: =IF(H12=0,0,(H12-G12)/H12) -> 0.41485086
A13: SKU-10070 | B13: Fontanería ref. 665 | C13: Fontanería | D13: 326 | E13: 20 | F13: Pasillo 2 - B3 | G13: 40.38 | H13: 63.6 | I13: =D13*G13 -> 13163.88 | J13: =IF(D13<E13,"Sí","No") -> No | K13: =IF(H13=0,0,(H13-G13)/H13) -> 0.36509434
A14: SKU-10077 | B14: Electricidad ref. 356 | C14: Electricidad | D14: 346 | E14: 20 | F14: Pasillo 4 - C2 | G14: 57.22 | H14: 118.52 | I14: =D14*G14 -> 19798.12 | J14: =IF(D14<E14,"Sí","No") -> No | K14: =IF(H14=0,0,(H14-G14)/H14) -> 0.51721228
... A122: SKU-10833 | B122: Electricidad ref. 255 | C122: Electricidad | D122: 333 | E122: 20 | F122: Pasillo 7 - C5 | G122: 60.75 | H122: 92.43 | I122: =D122*G122 -> 20229.75 | J122: =IF(D122<E122,"Sí","No") -> No | K122: =IF(H122=0,0,(H122-G122)/H122) -> 0.34274586
A124: Total | D124: =SUBTOTAL(9,D3:D122) -> 23805 | I124: =SUBTOTAL(9,I3:I122) -> 968155.96
A125: Total (SUM) | D125: =SUM(D3:D122) -> 23805
A126: Total visibles (SUBTOTAL 109) | D126: =SUBTOTAL(109,D3:D122) -> 23075 | I126: =SUBTOTAL(109,I3:I122) -> 953259.46
A127: Productos a reponer | D127: =COUNTIF(J3:J122,"Sí") -> 5

Sheet Resumen
A1: Provincia | B1: Clientes | C1: Activos | D1: Saldo pendiente | E1: Límite medio
A2: A Coruña | B2: =COUNTIF(Clientes!$G$2:$G$251,A2) -> 18 | C2: =COUNTIFS(Clientes!$G$2:$G$251,A2,Clientes!$K$2:$K$251,TRUE) -> 13 | D2: =SUMIF(Clientes!$G$2:$G$251,A2,Clientes!$M$2:$M$251) -> 111183.9 | E2: =AVERAGEIF(Clientes!$G$2:$G$251,A2,Clientes!$L$2:$L$251) -> 10111.111
A3: Asturias | B3: =COUNTIF(Clientes!$G$2:$G$251,A3) -> 8 | C3: =COUNTIFS(Clientes!$G$2:$G$251,A3,Clientes!$K$2:$K$251,TRUE) -> 6 | D3: =SUMIF(Clientes!$G$2:$G$251,A3,Clientes!$M$2:$M$251) -> 49558.12 | E3: =AVERAGEIF(Clientes!$G$2:$G$251,A3,Clientes!$L$2:$L$251) -> 7875
A4: Barcelona | B4: =COUNTIF(Clientes!$G$2:$G$251,A4) -> 25 | C4: =COUNTIFS(Clientes!$G$2:$G$251,A4,Clientes!$K$2:$K$251,TRUE) -> 18 | D4: =SUMIF(Clientes!$G$2:$G$251,A4,Clientes!$M$2:$M$251) -> 153524.64 | E4: =AVERAGEIF(Clientes!$G$2:$G$251,A4,Clientes!$L$2:$L$251) -> 10360
A5: Bizkaia | B5: =COUNTIF(Clientes!$G$2:$G$251,A5) -> 16 | C5: =COUNTIFS(Clientes!$G$2:$G$251,A5,Clientes!$K$2:$K$251,TRUE) -> 14 | D5: =SUMIF(Clientes!$G$2:$G$251,A5,Clientes!$M$2:$M$251) -> 81788.73 | E5: =AVERAGEIF(Clientes!$G$2:$G$251,A5,Clientes!$L$2:$L$251) -> 6750
A6: Castellón | B6: =COUNTIF(Clientes!$G$2:$G$251,A6) -> 21 | C6: =COUNTIFS(Clientes!$G$2:$G$251,A6,Clientes!$K$2:$K$251,TRUE) -> 16 | D6: =SUMIF(Clientes!$G$2:$G$251,A6,Clientes!$M$2:$M$251) -> 192256.63 | E6: =AVERAGEIF(Clientes!$G$2:$G$251,A6,Clientes!$L$2:$L$251) -> 12666.667
A7: Cádiz | B7: =COUNTIF(Clientes!$G$2:$G$251,A7) -> 19 | C7: =COUNTIFS(Clientes!$G$2:$G$251,A7,Clientes!$K$2:$K$251,TRUE) -> 16 | D7: =SUMIF(Clientes!$G$2:$G$251,A7,Clientes!$M$2:$M$251) -> 129988.79 | E7: =AVERAGEIF(Clientes!$G$2:$G$251,A7,Clientes!$L$2:$L$251) -> 12368.421
A8: Córdoba | B8: =COUNTIF(Clientes!$G$2:$G$251,A8) -> 11 | C8: =COUNTIFS(Clientes!$G$2:$G$251,A8,Clientes!$K$2:$K$251,TRUE) -> 8 | D8: =SUMIF(Clientes!$G$2:$G$251,A8,Clientes!$M$2:$M$251) -> 35675.85 | E8: =AVERAGEIF(Clientes!$G$2:$G$251,A8,Clientes!$L$2:$L$251) -> 6454.5455
A9: La Rioja | B9: =COUNTIF(Clientes!$G$2:$G$251,A9) -> 12 | C9: =COUNTIFS(Clientes!$G$2:$G$251,A9,Clientes!$K$2:$K$251,TRUE) -> 8 | D9: =SUMIF(Clientes!$G$2:$G$251,A9,Clientes!$M$2:$M$251) -> 88370.17 | E9: =AVERAGEIF(Clientes!$G$2:$G$251,A9,Clientes!$L$2:$L$251) -> 12250
A10: Madrid | B10: =COUNTIF(Clientes!$G$2:$G$251,A10) -> 36 | C10: =COUNTIFS(Clientes!$G$2:$G$251,A10,Clientes!$K$2:$K$251,TRUE) -> 24 | D10: =SUMIF(Clientes!$G$2:$G$251,A10,Clientes!$M$2:$M$251) -> 210755.18 | E10: =AVERAGEIF(Clientes!$G$2:$G$251,A10,Clientes!$L$2:$L$251) -> 9472.2222
A11: Málaga | B11: =COUNTIF(Clientes!$G$2:$G$251,A11) -> 17 | C11: =COUNTIFS(Clientes!$G$2:$G$251,A11,Clientes!$K$2:$K$251,TRUE) -> 12 | D11: =SUMIF(Clientes!$G$2:$G$251,A11,Clientes!$M$2:$M$251) -> 97726.18 | E11: =AVERAGEIF(Clientes!$G$2:$G$251,A11,Clientes!$L$2:$L$251) -> 9117.6471
A12: Sevilla | B12: =COUNTIF(Clientes!$G$2:$G$251,A12) -> 16 | C12: =COUNTIFS(Clientes!$G$2:$G$251,A12,Clientes!$K$2:$K$251,TRUE) -> 15 | D12: =SUMIF(Clientes!$G$2:$G$251,A12,Clientes!$M$2:$M$251) -> 108963.52 | E12: =AVERAGEIF(Clientes!$G$2:$G$251,A12,Clientes!$L$2:$L$251) -> 10562.5
A13: Valencia | B13: =COUNTIF(Clientes!$G$2:$G$251,A13) -> 13 | C13: =COUNTIFS(Clientes!$G$2:$G$251,A13,Clientes!$K$2:$K$251,TRUE) -> 9 | D13: =SUMIF(Clientes!$G$2:$G$251,A13,Clientes!$M$2:$M$251) -> 98313.39 | E13: =AVERAGEIF(Clientes!$G$2:$G$251,A13,Clientes!$L$2:$L$251) -> 11461.538
... A15: Ávila | B15: =COUNTIF(Clientes!$G$2:$G$251,A15) -> 19 | C15: =COUNTIFS(Clientes!$G$2:$G$251,A15,Clientes!$K$2:$K$251,TRUE) -> 16 | D15: =SUMIF(Clientes!$G$2:$G$251,A15,Clientes!$M$2:$M$251) -> 134887.2 | E15: =AVERAGEIF(Clientes!$G$2:$G$251,A15,Clientes!$L$2:$L$251) -> 11210.526
A17: Total clientes | B17: =COUNTA(Clientes!A2:A251) -> 250
A18: Saldo máximo | B18: =MAX(Clientes!M2:M251) -> 23904.95
A19: Tercer mayor saldo | B19: =LARGE(Clientes!M2:M251,3) -> 23079.2
A20: Mediana saldo | B20: =MEDIAN(Clientes!M2:M251) -> 4048.395
A21: Clientes riesgo alto | B21: =COUNTIF(Clientes!N2:N251,"Alto") -> 43
